<mujoco>
    <worldbody>
        <geom type="plane" pos="0 0 0" size="10 10 0.1" rgba="0.5 0.5 0.5 1"/>
        <body name="test_box" pos="0 0 0.5">
            <geom type="box" size="0.2 0.3 0.1" rgba="1 0 0 1"/>
            <body name="forearm" pos="0 0 0.6">
                <geom type="capsule" size="0.05 0.5"/>
                <joint name="elbow_joint" type="hinge" axis="0 1 0" range="-90 90"/>
            </body>        
        </body>
    </worldbody>
    <actuator>
        <motor name="elbow_motor" joint="elbow_joint" gear="100"/>
    </actuator>
    <!-- <equality> -->
        
    <!-- </equality> -->
</mujoco>
